<?xml version="1.0" ?>
<robot name="FASTbot">
	<gazebo>
		<plugin name="gazebo_ros_control" filename="libgazebo_ros_control.so">
			<robotNamespace>/FASTbot</robotNamespace>
		</plugin>
	</gazebo>

	<!--gazebo reference="base_link">
		<kp>1000.0</kp>
		<kd>10.0</kd>
		<mu1>10.0</mu1>
		<mu2>10.0</mu2>
		<material>Gazebo/White</material>
	</gazebo-->

	<link name="base_link">
		<visual>
			<origin rpy="0 0 0" xyz="0 0 0" />
			<geometry>
				<box size="1 1 1" />
			</geometry>
			<material name="White">
				<color rgba="1.0 1.0 1.0 1.0"/>
			</material>
		</visual>
		<collision>
			<origin rpy="0 0 0" xyz="0 0 0" />
			<geometry>
				<box size="1 1 1" />
			</geometry>
		</collision>
		<inertial>
			<mass value="1024" />
			<origin rpy="0 0 0" xyz="0 0 0" />
			<inertia ixx="170.667" ixy="0" ixz="0" iyy="170.667" iyz="0" izz="170.667" />
		</inertial>
	</link>

	<joint name="base_link_link_1" type="revolute">
		<axis xyz="0 0 1"/>
		<limit effort="10000.0" lower="-3.14" upper="3.14" velocity="0.5"/>
		<origin rpy="0 0 0" xyz="0 0 0.5"/>
		<parent link="base_link"/>
		<child link="link_1"/>
	</joint>

	<transmission name="trans_base_link_link_1">
		<type>transmission_interface/SimpleTransmission</type>
		<joint name="base_link_link_1">
			<hardwareInterface>hardware_interface/EffortJointInterface</hardwareInterface>
		</joint>
		<actuator name="motor_base_link_link_1">
			<hardwareInterface>hardware_interface/EffortJointInterface</hardwareInterface>
			<mechanicalReduction>1</mechanicalReduction>
		</actuator>	
	</transmission>

	<gazebo reference="link_1">
		<kp>1000.0</kp>
		<kd>10.0</kd>
		<mu1>10.0</mu1>
		<mu2>10.0</mu2>
		<material>Gazebo/Blue</material>
	</gazebo>

	<link name="link_1">
		<visual>
			<origin rpy="0 0 0" xyz="0 0 0.2" />
			<geometry>
				<cylinder radius="0.35" length="0.4" />
			</geometry>
			<material name="Blue">
				<color rgba="0.0 0.0 1.0 1.0"/>
			</material>
		</visual>
		<collision>
			<origin rpy="0 0 0" xyz="0 0 0.2" />
			<geometry>
				<cylinder radius="0.35" length="0.4" />
			</geometry>
		</collision>
		<inertial>
			<mass value="157.633" />
			<origin rpy="0 0 0" xyz="0 0 0.2" />
			<inertia ixx="13.235" ixy="0" ixz="0" iyy="13.235" iyz="0" izz="9.655" />
		</inertial>
	</link>

	<joint name="link_1_link_2" type="revolute">
		<axis xyz="0 1 0"/>
		<limit effort="10000.0" lower="-3.14" upper="3.14" velocity="0.5"/>
		<origin rpy="0 0 0" xyz="0 0 0.4"/>
		<parent link="link_1"/>
		<child link="link_2"/>
	</joint>

	<transmission name="trans_link_1_link_2">
		<type>transmission_interface/SimpleTransmission</type>
		<joint name="link_1_link_2">
			<hardwareInterface>hardware_interface/EffortJointInterface</hardwareInterface>
		</joint>
		<actuator name="motor_link_1_link_2">
			<hardwareInterface>hardware_interface/EffortJointInterface</hardwareInterface>
			<mechanicalReduction>1</mechanicalReduction>
		</actuator>	
	</transmission>

	<gazebo reference="link_2">
		<kp>1000.0</kp>
		<kd>10.0</kd>
		<mu1>10.0</mu1>
		<mu2>10.0</mu2>
		<material>Gazebo/White</material>
	</gazebo>

	<link name="link_2">
		<visual>
			<origin rpy="0 0 0" xyz="0 0 0.4" />
			<geometry>
				<cylinder radius="0.15" length="0.8" />
			</geometry>
			<material name="White">
				<color rgba="1.0 1.0 1.0 1.0"/>
			</material>
		</visual>
		<collision>
			<origin rpy="0 0 0" xyz="0 0 0.4" />
			<geometry>
				<cylinder radius="0.15" length="0.8" />
			</geometry>
		</collision>
		<inertial>
			<mass value="57.906" />
			<origin rpy="0 0 0" xyz="0 0 0.4" />
			<inertia ixx="12.679" ixy="0" ixz="0" iyy="12.679" iyz="0" izz="0.651" />
		</inertial>
	</link>

	<joint name="link_2_link_3" type="revolute">
		<axis xyz="0 1 0"/>
		<limit effort="10000.0" lower="-3.14" upper="3.14" velocity="0.5"/>
		<origin rpy="0 0 0" xyz="0 0 0.8"/>
		<parent link="link_2"/>
		<child link="link_3"/>
	</joint>

	<transmission name="trans_link_2_link_3">
		<type>transmission_interface/SimpleTransmission</type>
		<joint name="link_2_link_3">
			<hardwareInterface>hardware_interface/EffortJointInterface</hardwareInterface>
		</joint>
		<actuator name="motor_link_2_link_3">
			<hardwareInterface>hardware_interface/EffortJointInterface</hardwareInterface>
			<mechanicalReduction>1</mechanicalReduction>
		</actuator>	
	</transmission>

	<gazebo reference="link_3">
		<kp>1000.0</kp>
		<kd>10.0</kd>
		<mu1>10.0</mu1>
		<mu2>10.0</mu2>
		<material>Gazebo/Blue</material>
	</gazebo>

	<link name="link_3">
		<visual>
			<origin rpy="0 0 0" xyz="0 0 0.4" />
			<geometry>
				<cylinder radius="0.15" length="0.8" />
			</geometry>
			<material name="Blue">
				<color rgba="0.0 0.0 1.0 1.0"/>
			</material>
		</visual>
		<collision>
			<origin rpy="0 0 0" xyz="0 0 0.4" />
			<geometry>
				<cylinder radius="0.15" length="0.8" />
			</geometry>
		</collision>
		<inertial>
			<mass value="57.906" />
			<origin rpy="0 0 0" xyz="0 0 0.4" />
			<inertia ixx="12.679" ixy="0" ixz="0" iyy="12.679" iyz="0" izz="0.651" />
		</inertial>
	</link>

	<joint name="link_3_link_4" type="revolute">
		<axis xyz="0 1 0"/>
		<limit effort="10000.0" lower="-3.14" upper="3.14" velocity="0.5"/>
		<origin rpy="0 0 0" xyz="0 0 0.8"/>
		<parent link="link_3"/>
		<child link="link_4"/>
	</joint>

	<transmission name="trans_link_3_link_4">
		<type>transmission_interface/SimpleTransmission</type>
		<joint name="link_3_link_4">
			<hardwareInterface>hardware_interface/EffortJointInterface</hardwareInterface>
		</joint>
		<actuator name="motor_link_3_link_4">
			<hardwareInterface>hardware_interface/EffortJointInterface</hardwareInterface>
			<mechanicalReduction>1</mechanicalReduction>
		</actuator>	
	</transmission>

	<gazebo reference="link_4">
		<kp>1000.0</kp>
		<kd>10.0</kd>
		<mu1>10.0</mu1>
		<mu2>10.0</mu2>
		<material>Gazebo/White</material>
	</gazebo>

	<link name="link_4">
		<visual>
			<origin rpy="0 0 0" xyz="0 0 0.4" />
			<geometry>
				<cylinder radius="0.15" length="0.8" />
			</geometry>
			<material name="White">
				<color rgba="1.0 1.0 1.0 1.0"/>
			</material>
		</visual>
		<collision>
			<origin rpy="0 0 0" xyz="0 0 0.4" />
			<geometry>
				<cylinder radius="0.15" length="0.8" />
			</geometry>
		</collision>
		<inertial>
			<mass value="57.906" />
			<origin rpy="0 0 0" xyz="0 0 0.4" />
			<inertia ixx="12.679" ixy="0" ixz="0" iyy="12.679" iyz="0" izz="0.651" />
		</inertial>
	</link>

	<joint name="link_4_link_5" type="revolute">
		<axis xyz="0 0 1"/>
		<limit effort="10000.0" lower="-3.14" upper="3.14" velocity="0.5"/>
		<origin rpy="0 0 0" xyz="0 0 0.8"/>
		<parent link="link_4"/>
		<child link="link_5"/>
	</joint>

	<transmission name="trans_link_4_link_5">
		<type>transmission_interface/SimpleTransmission</type>
		<joint name="link_4_link_5">
			<hardwareInterface>hardware_interface/EffortJointInterface</hardwareInterface>
		</joint>
		<actuator name="motor_link_4_link_5">
			<hardwareInterface>hardware_interface/EffortJointInterface</hardwareInterface>
			<mechanicalReduction>1</mechanicalReduction>
		</actuator>	
	</transmission>

	<gazebo reference="link_5">
		<kp>1000.0</kp>
		<kd>10.0</kd>
		<mu1>10.0</mu1>
		<mu2>10.0</mu2>
		<material>Gazebo/Blue</material>
	</gazebo>

	<link name="link_5">
		<visual>
			<origin rpy="0 0 0" xyz="0 0 0.125" />
			<geometry>
				<cylinder radius="0.15" length="0.25" />
			</geometry>
			<material name="Blue">
				<color rgba="0.0 0.0 1.0 1.0"/>
			</material>
		</visual>
		<collision>
			<origin rpy="0 0 0" xyz="0 0 0.125" />
			<geometry>
				<cylinder radius="0.15" length="0.25" />
			</geometry>
		</collision>
		<inertial>
			<mass value="18.056" />
			<origin rpy="0 0 0" xyz="0 0 0.125" />
			<inertia ixx="0.479" ixy="0" ixz="0" iyy="0.479" iyz="0" izz="0.204" />
		</inertial>
	</link>
</robot>
