<?xml version="1.0" ?>
<robot xmlns:xacro="http://ros.org/wiki/xacro">
	<xacro:macro name="motoman_sia20d" params="prefix">
		<xacro:include filename="$(find motoman_resources)/urdf/common_materials.xacro"/>
		<xacro:include filename="$(find wsg50_gripper)/urdf/wsg_50.urdf.xacro"/>

		<!-- link list -->
		<link name="${prefix}base_link">
			<visual>
				<geometry>
					<mesh filename="package://motoman_sia20d_support/meshes/sia20d/visual/MOTOMAN_BASE.stl" />
				</geometry>
				<xacro:material_yaskawa_blue/>
			</visual>
			<collision>
				<geometry>
					<mesh filename="package://motoman_sia20d_support/meshes/sia20d/collision/MOTOMAN_BASE.stl" />
				</geometry>
				<xacro:material_yaskawa_yellow/>
			</collision>
		</link>
		<link name="${prefix}link_s">
			<visual>
				<origin rpy="0 0 3.1416" xyz="0 0 0"/>
				<geometry>
					<mesh filename="package://motoman_sia20d_support/meshes/sia20d/visual/MOTOMAN_AXIS_S.stl"/>
				</geometry>
				<xacro:material_yaskawa_white/>
			</visual>
			<collision>
				<origin rpy="0 0 3.1416" xyz="0 0 0"/>
				<geometry>
					<mesh filename="package://motoman_sia20d_support/meshes/sia20d/collision/MOTOMAN_AXIS_S.stl" />
				</geometry>
				<xacro:material_yaskawa_yellow/>
			</collision>
		</link>
		<link name="${prefix}link_l">
			<visual>
				<origin rpy="1.57 3.1416 3.1416" xyz="0 0 0"/>
				<geometry>
					<mesh filename="package://motoman_sia20d_support/meshes/sia20d/visual/MOTOMAN_AXIS_L.stl"/>
				</geometry>
				<xacro:material_yaskawa_blue/>
			</visual>
			<collision>
				<origin rpy="1.57 3.1416 3.1416" xyz="0 0 0"/>
				<geometry>
					<mesh filename="package://motoman_sia20d_support/meshes/sia20d/collision/MOTOMAN_AXIS_L.stl"/>
				</geometry>
				<xacro:material_yaskawa_yellow/>
			</collision>
		</link>
		<link name="${prefix}link_e">
			<visual>
				<origin rpy="0 0 0" xyz="0 0 0"/>
				<geometry>
					<mesh filename="package://motoman_sia20d_support/meshes/sia20d/visual/MOTOMAN_AXIS_E.stl"/>
				</geometry>
				<xacro:material_yaskawa_white/>
			</visual>
			<collision>
				<origin rpy="0 0 0" xyz="0 0 0"/>
				<geometry>
					<mesh filename="package://motoman_sia20d_support/meshes/sia20d/collision/MOTOMAN_AXIS_E.stl"/>
				</geometry>
				<xacro:material_yaskawa_yellow/>
			</collision>
		</link>
		<link name="${prefix}link_u">
			<visual>
				<origin rpy="1.57 -3.1415 3.1416" xyz="0 0 0"/>
				<geometry>
					<mesh filename="package://motoman_sia20d_support/meshes/sia20d/visual/MOTOMAN_AXIS_U.stl"/>
				</geometry>
				<xacro:material_yaskawa_blue/>
			</visual>
			<collision>
				<origin rpy="1.57 -3.1415 3.1416" xyz="0 0 0"/>
				<geometry>
					<mesh filename="package://motoman_sia20d_support/meshes/sia20d/collision/MOTOMAN_AXIS_U.stl"/>
				</geometry>
				<xacro:material_yaskawa_yellow/>
			</collision>
		</link>
		<link name="${prefix}link_r">
			<visual>
				<origin rpy="0 0 0" xyz="0 0 0"/>
				<geometry>
					<mesh filename="package://motoman_sia20d_support/meshes/sia20d/visual/MOTOMAN_AXIS_R.stl"/>
				</geometry>
				<xacro:material_yaskawa_white/>
			</visual>
			<collision>
				<origin rpy="0 0 0" xyz="0 0 0"/>
				<geometry>
					<mesh filename="package://motoman_sia20d_support/meshes/sia20d/collision/MOTOMAN_AXIS_R.stl"/>
				</geometry>
				<xacro:material_yaskawa_yellow/>
			</collision>
		</link>
		<link name="${prefix}link_b">
			<visual>
				<origin rpy="-1.57 0 0" xyz="0 0 0"/>
				<geometry>
					<mesh filename="package://motoman_sia20d_support/meshes/sia20d/visual/MOTOMAN_AXIS_B.stl"/>
				</geometry>
				<xacro:material_yaskawa_blue/>
			</visual>
			<collision>
				<origin rpy="-1.57 0 0" xyz="0 0 0"/>
				<geometry>
					<mesh filename="package://motoman_sia20d_support/meshes/sia20d/collision/MOTOMAN_AXIS_B.stl"/>
				</geometry>
				<xacro:material_yaskawa_yellow/>
			</collision>
		</link>
		<link name="${prefix}link_t">
			<visual>
				<geometry>
					<mesh filename="package://motoman_sia20d_support/meshes/sia20d/visual/MOTOMAN_AXIS_T.stl" />
				</geometry>
				<xacro:material_yaskawa_white/>
			</visual>
			<collision>
				<geometry>
					<mesh filename="package://motoman_sia20d_support/meshes/sia20d/collision/MOTOMAN_AXIS_T.stl" />
				</geometry>
				<xacro:material_yaskawa_yellow/>
			</collision>
		</link>
		<!-- end of link list -->
		<!-- joint list -->
		<joint name="${prefix}joint_s" type="revolute">
			<parent link="${prefix}base_link"/>
			<child link="${prefix}link_s"/>
			<origin xyz="0 0 0.41" rpy="0 0 0"/>
			<axis xyz="0 0 1" />
			<limit lower="-3.1415" upper="3.1415" effort="100" velocity="2.2689" />
		</joint>
		<joint name="${prefix}joint_l" type="revolute">
			<parent link="${prefix}link_s"/>
			<child link="${prefix}link_l"/>
			<origin xyz="0 0 0" rpy="0 0 0"/>
			<axis xyz="0 1 0" />
			<limit lower="-1.9198" upper="1.9198" effort="100" velocity="2.2689" />
		</joint>
		<joint name="${prefix}joint_e" type="revolute">
			<parent link="${prefix}link_l"/>
			<child link="${prefix}link_e"/>
			<origin xyz="0 0 0.49" rpy="0 0 0"/>
			<axis xyz="0 0 1" />
			<limit lower="-2.9670" upper="2.9670" effort="100" velocity="2.9670" />
		</joint>
		<joint name="${prefix}joint_u" type="revolute">
			<parent link="${prefix}link_e"/>
			<child link="${prefix}link_u"/>
			<origin xyz="0 0 0" rpy="0 0 0"/>
			<axis xyz="0 -1 0" />
			<limit lower="-2.2689" upper="2.2689" effort="100" velocity="2.9670" />
		</joint>
		<joint name="${prefix}joint_r" type="revolute">
			<parent link="${prefix}link_u"/>
			<child link="${prefix}link_r"/>
			<origin xyz="0 0 0.420" rpy="0 0 0"/>
			<axis xyz="0 0 -1" />
			<limit lower="-3.1415" upper="3.1415" effort="100" velocity="3.4906" />
		</joint>
		<joint name="${prefix}joint_b" type="revolute">
			<parent link="${prefix}link_r"/>
			<child link="${prefix}link_b"/>
			<origin xyz="0 0 0" rpy="0 0 0"/>
			<axis xyz="0 -1 0" />
			<limit lower="-1.9198" upper="1.9198" effort="100" velocity="3.4906" />
		</joint>
		<joint name="${prefix}joint_t" type="revolute">
			<parent link="${prefix}link_b"/>
			<child link="${prefix}link_t"/>
			<origin xyz="0 0 0.18" rpy="0 0 0"/>
			<axis xyz="0 0 -1" />
			<limit lower="-3.1415" upper="3.1415" effort="100" velocity="6.9813" />
		</joint>

		<!-- end of joint list -->
		
    <!-- My addition: the tool -->
    <xacro:wsg_50_xacro name="${prefix}wsg" finger_length="0.22" finger_tip="0.0"/>
		<joint name="${prefix}lint_t-wsg" type="fixed">
			<parent link="${prefix}link_t"/>
			<child link="${prefix}wsg_base_link"/>
			<origin xyz="0 0 0" rpy="0 0 -3.1415926535"/>
		</joint>
		

		<!-- ROS base_link (via base_link) to Motoman Robot (not Base) Frame transform -->
		<link name="${prefix}base" />
		<joint name="${prefix}base_link-base" type="fixed">
			<origin xyz="0 0 0.410" rpy="0 0 0"/>
			<parent link="${prefix}base_link"/>
			<child link="${prefix}base"/>
		</joint>
	</xacro:macro>
</robot>
